Workbook

Sheet Worksheet
A1: key | B1: lookup | C1: Date | D1: Flight No. | E1: Type of Flight | F1: EU ETS Annex I exceptions | G1: Aircraft Type | H1: Reg No. | I1: Country of dep. | J1: Departure | K1: Airport of dep. (ICAO code) | L1: Airport of dep. (IATA code) | M1: Airport of dep geog. boundaries | N1: Country of arrival | O1: Arrival | P1: Airport of arrival (ICAO code) | Q1: Airport of arrival (IATA code) | R1: Airport of arrival geog. boundaries | S1: Great circle distance [km] | T1: Payload distance [km] | U1: Block | V1: Remaining fuel from previous block on [kg] | W1: Fuel uplift [kg] | X1: Block Fuel [kg] | Y1: Density [kg/L] | Z1: Fuel at block-on [kg] | AA1: Fuel consumption [kg] | AB1: PAX | AC1: PAX infant | AD1: PAX child | AE1: PAX male | AF1: PAX female | AG1: Gross weight of baggage [kg] | AH1: Gross weight of freight [kg] | AI1: Payload [kg] | AJ1: kmT | AK1: emission CO2 [t CO2] | AL1: emission ETS [t C02] | AM1: emission Corsia [t C02]
A2: =CONCATENATE(D2,K2,TEXT(C2,"YYYY-MM-DD")) -> HFA703LLHA2026-01-04 | B2: =VLOOKUP(A2,Sheet1!A2:B1344,1,FALSE) -> HFA703LLHA2026-01-04 | C2: 46026 | D2: HFA703 | E2: SCD | G2: AT76 | H2: 4X-IHA | I2: ISR | J2: Haifa/U Michaeli | K2: LLHA | L2: HFA | M2: NEU | N2: GRC | O2: Athens Intl Eleftherios Venizelos | P2: LGAV | Q2: ATH | R2: EU | S2: 1157 | T2: 0 | U2: 0.12013889 | V2: 2100 | W2: 1000 | X2: 3100 | Y2: No | Z2: 1370 | AA2: 1730 | AB2: 0 | AC2: 0 | AD2: 0 | AE2: 0 | AG2: 0 | AH2: 0 | AI2: 0 | AJ2: 0 | AK2: 5.4668 | AL2: 5.4668 | AM2: 5.4668
A3: =CONCATENATE(D3,K3,TEXT(C3,"YYYY-MM-DD")) -> HFA704LGAV2026-01-04 | B3: =VLOOKUP(A3,Sheet1!A3:B1345,1,FALSE) -> HFA704LGAV2026-01-04 | C3: 46026 | D3: HFA704 | E3: SCD | G3: AT76 | H3: 4X-IHA | I3: GRC | J3: Athens Intl Eleftherios Venizelos | K3: LGAV | L3: ATH | M3: EU | N3: ISR | O3: Haifa/U Michaeli | P3: LLHA | Q3: HFA | R3: NEU | S3: 1157 | T3: 0 | U3: 0.11111111 | V3: 1370 | W3: 1730 | X3: 3100 | Y3: No | Z3: 1440 | AA3: 1660 | AB3: 0 | AC3: 0 | AD3: 0 | AE3: 0 | AG3: 0 | AH3: 0 | AI3: 0 | AJ3: 0 | AK3: 5.2456 | AL3: 5.2456 | AM3: 5.2456
A4: =CONCATENATE(D4,K4,TEXT(C4,"YYYY-MM-DD")) -> HFA701LLHA2026-01-07 | B4: =VLOOKUP(A4,Sheet1!A4:B1346,1,FALSE) -> HFA701LLHA2026-01-07 | C4: 46029 | D4: HFA701 | E4: SCD | F4: Both airfields outside EU | G4: AT76 | H4: 4X-IHA | I4: ISR | J4: Haifa/U Michaeli | K4: LLHA | L4: HFA | M4: NEU | N4: ISR | O4: Haifa/U Michaeli | P4: LLHA | Q4: HFA | R4: NEU | S4: 0 | T4: 0 | U4: 0.05 | V4: 1440 | W4: 1760 | X4: 3200 | Y4: No | Z4: 2580 | AA4: 620 | AB4: 0 | AC4: 0 | AD4: 0 | AE4: 0 | AG4: 0 | AH4: 0 | AI4: 0 | AJ4: 0 | AK4: 1.9592 | AL4: 1.9592 | AM4: 1.9592
A5: =CONCATENATE(D5,K5,TEXT(C5,"YYYY-MM-DD")) -> HFA701ALLHA2026-01-07 | B5: =VLOOKUP(A5,Sheet1!A5:B1347,1,FALSE) -> HFA701ALLHA2026-01-07 | C5: 46029 | D5: HFA701A | E5: SCD | G5: AT76 | H5: 4X-IHA | I5: ISR | J5: Haifa/U Michaeli | K5: LLHA | L5: HFA | M5: NEU | N5: GRC | O5: Athens Intl Eleftherios Venizelos | P5: LGAV | Q5: ATH | R5: EU | S5: 1157 | T5: 1158 | U5: 0.13402778 | V5: 2580 | W5: 620 | X5: 3200 | Y5: No | Z5: 1090 | AA5: 2110 | AB5: 0 | AC5: 0 | AD5: 0 | AE5: 0 | AG5: 0 | AH5: 0 | AI5: 0 | AJ5: 0 | AK5: 6.6676 | AL5: 6.6676 | AM5: 6.6676
A6: =CONCATENATE(D6,K6,TEXT(C6,"YYYY-MM-DD")) -> HFA702LGAV2026-01-07 | B6: =VLOOKUP(A6,Sheet1!A6:B1348,1,FALSE) -> HFA702LGAV2026-01-07 | C6: 46029 | D6: HFA702 | E6: SCD | G6: AT76 | H6: 4X-IHA | I6: GRC | J6: Athens Intl Eleftherios Venizelos | K6: LGAV | L6: ATH | M6: EU | N6: ISR | O6: Haifa/U Michaeli | P6: LLHA | Q6: HFA | R6: NEU | S6: 1157 | T6: 0 | U6: 0.10486111 | V6: 1090 | W6: 2110 | X6: 3200 | Y6: No | Z6: 1810 | AA6: 1390 | AB6: 0 | AC6: 0 | AD6: 0 | AE6: 0 | AG6: 0 | AH6: 0 | AI6: 0 | AJ6: 0 | AK6: 4.3924 | AL6: 4.3924 | AM6: 4.3924
A7: =CONCATENATE(D7,K7,TEXT(C7,"YYYY-MM-DD")) -> HFA601LLHA2026-01-08 | B7: =VLOOKUP(A7,Sheet1!A7:B1349,1,FALSE) -> HFA601LLHA2026-01-08 | C7: 46030 | D7: HFA601 | E7: SCD | F7: Both airfields outside EU | G7: AT76 | H7: 4X-IHA | I7: ISR | J7: Haifa/U Michaeli | K7: LLHA | L7: HFA | M7: NEU | N7: ISR | O7: Eilat/Ilan and Assaf Ramon Intl (Timna) | P7: LLER | Q7: ETM | R7: NEU | S7: 342 | T7: 0 | U7: 0.048611111 | V7: 1810 | W7: 0 | X7: 1810 | Y7: No | Z7: 1040 | AA7: 770 | AB7: 0 | AC7: 0 | AD7: 0 | AE7: 0 | AG7: 0 | AH7: 0 | AI7: 0 | AJ7: 0 | AK7: 2.4332 | AL7: 2.4332 | AM7: 2.4332
A8: =CONCATENATE(D8,K8,TEXT(C8,"YYYY-MM-DD")) -> HFA602LLER2026-01-08 | B8: =VLOOKUP(A8,Sheet1!A8:B1350,1,FALSE) -> HFA602LLER2026-01-08 | C8: 46030 | D8: HFA602 | E8: SCD | F8: Both airfields outside EU | G8: AT76 | H8: 4X-IHA | I8: ISR | J8: Eilat/Ilan and Assaf Ramon Intl (Timna) | K8: LLER | L8: ETM | M8: NEU | N8: ISR | O8: Haifa/U Michaeli | P8: LLHA | Q8: HFA | R8: NEU | S8: 342 | T8: 0 | U8: 0.041666667 | V8: 1040 | W8: 1560 | X8: 2600 | Y8: No | Z8: 2000 | AA8: 600 | AB8: 0 | AC8: 0 | AD8: 0 | AE8: 0 | AG8: 0 | AH8: 0 | AI8: 0 | AJ8: 0 | AK8: 1.896 | AL8: 1.896 | AM8: 1.896
A9: =CONCATENATE(D9,K9,TEXT(C9,"YYYY-MM-DD")) -> HFA703LLHA2026-01-08 | B9: =VLOOKUP(A9,Sheet1!A9:B1351,1,FALSE) -> HFA703LLHA2026-01-08 | C9: 46030 | D9: HFA703 | E9: SCD | G9: AT76 | H9: 4X-IHA | I9: ISR | J9: Haifa/U Michaeli | K9: LLHA | L9: HFA | M9: NEU | N9: GRC | O9: Athens Intl Eleftherios Venizelos | P9: LGAV | Q9: ATH | R9: EU | S9: 1157 | T9: 0 | U9: 0.12847222 | V9: 2000 | W9: 1100 | X9: 3100 | Y9: No | Z9: 1050 | AA9: 2050 | AB9: 0 | AC9: 0 | AD9: 0 | AE9: 0 | AG9: 0 | AH9: 0 | AI9: 0 | AJ9: 0 | AK9: 6.478 | AL9: 6.478 | AM9: 6.478
A10: =CONCATENATE(D10,K10,TEXT(C10,"YYYY-MM-DD")) -> HFA704LGAV2026-01-08 | B10: =VLOOKUP(A10,Sheet1!A10:B1352,1,FALSE) -> HFA704LGAV2026-01-08 | C10: 46030 | D10: HFA704 | E10: SCD | G10: AT76 | H10: 4X-IHA | I10: GRC | J10: Athens Intl Eleftherios Venizelos | K10: LGAV | L10: ATH | M10: EU | N10: ISR | O10: Haifa/U Michaeli | P10: LLHA | Q10: HFA | R10: NEU | S10: 1157 | T10: 0 | U10: 0.10763889 | V10: 1050 | W10: 2250 | X10: 3300 | Y10: No | Z10: 1770 | AA10: 1530 | AB10: 0 | AC10: 0 | AD10: 0 | AE10: 0 | AG10: 0 | AH10: 0 | AI10: 0 | AJ10: 0 | AK10: 4.8348 | AL10: 4.8348 | AM10: 4.8348
A11: =CONCATENATE(D11,K11,TEXT(C11,"YYYY-MM-DD")) -> HFA701LLHA2026-01-09 | B11: =VLOOKUP(A11,Sheet1!A11:B1353,1,FALSE) -> HFA701LLHA2026-01-09 | C11: 46031 | D11: HFA701 | E11: SCD | G11: AT76 | H11: 4X-IHA | I11: ISR | J11: Haifa/U Michaeli | K11: LLHA | L11: HFA | M11: NEU | N11: GRC | O11: Athens Intl Eleftherios Venizelos | P11: LGAV | Q11: ATH | R11: EU | S11: 1157 | T11: 0 | U11: 0.13958333 | V11: 1770 | W11: 1630 | X11: 3400 | Y11: No | Z11: 1290 | AA11: 2110 | AB11: 0 | AC11: 0 | AD11: 0 | AE11: 0 | AG11: 0 | AH11: 0 | AI11: 0 | AJ11: 0 | AK11: 6.6676 | AL11: 6.6676 | AM11: 6.6676
A12: =CONCATENATE(D12,K12,TEXT(C12,"YYYY-MM-DD")) -> HFA702LGAV2026-01-09 | B12: =VLOOKUP(A12,Sheet1!A12:B1354,1,FALSE) -> HFA702LGAV2026-01-09 | C12: 46031 | D12: HFA702 | E12: SCD | G12: AT76 | H12: 4X-IHA | I12: GRC | J12: Athens Intl Eleftherios Venizelos | K12: LGAV | L12: ATH | M12: EU | N12: ISR | O12: Haifa/U Michaeli | P12: LLHA | Q12: HFA | R12: NEU | S12: 1157 | T12: 0 | U12: 0.097916667 | V12: 1290 | W12: 2210 | X12: 3500 | Y12: No | Z12: 2240 | AA12: 1260 | AB12: 0 | AC12: 0 | AD12: 0 | AE12: 0 | AG12: 0 | AH12: 0 | AI12: 0 | AJ12: 0 | AK12: 3.9816 | AL12: 3.9816 | AM12: 3.9816
A13: =CONCATENATE(D13,K13,TEXT(C13,"YYYY-MM-DD")) -> HFA703LLHA2026-01-10 | B13: =VLOOKUP(A13,Sheet1!A13:B1355,1,FALSE) -> HFA703LLHA2026-01-10 | C13: 46032 | D13: HFA703 | E13: SCD | G13: AT76 | H13: 4X-IHA | I13: ISR | J13: Haifa/U Michaeli | K13: LLHA | L13: HFA | M13: NEU | N13: GRC | O13: Athens Intl Eleftherios Venizelos | P13: LGAV | Q13: ATH | R13: EU | S13: 1157 | T13: 0 | U13: 0.12222222 | V13: 2240 | W13: 960 | X13: 3200 | Y13: No | Z13: 1180 | AA13: 2020 | AB13: 0 | AC13: 0 | AD13: 0 | AE13: 0 | AG13: 0 | AH13: 0 | AI13: 0 | AJ13: 0 | AK13: 6.3832 | AL13: 6.3832 | AM13: 6.3832
A14: =CONCATENATE(D14,K14,TEXT(C14,"YYYY-MM-DD")) -> HFA704LGAV2026-01-10 | B14: =VLOOKUP(A14,Sheet1!A14:B1356,1,FALSE) -> HFA704LGAV2026-01-10 | C14: 46032 | D14: HFA704 | E14: SCD | G14: AT76 | H14: 4X-IHA | I14: GRC | J14: Athens Intl Eleftherios Venizelos | K14: LGAV | L14: ATH | M14: EU | N14: ISR | O14: Haifa/U Michaeli | P14: LLHA | Q14: HFA | R14: NEU | S14: 1157 | T14: 0 | U14: 0.1 | V14: 1180 | W14: 1720 | X14: 2900 | Y14: No | Z14: 1360 | AA14: 1540 | AB14: 0 | AC14: 0 | AD14: 0 | AE14: 0 | AG14: 0 | AH14: 0 | AI14: 0 | AJ14: 0 | AK14: 4.8664 | AL14: 4.8664 | AM14: 4.8664
A15: =CONCATENATE(D15,K15,TEXT(C15,"YYYY-MM-DD")) -> HFA701LLHA2026-01-11 | B15: =VLOOKUP(A15,Sheet1!A15:B1357,1,FALSE) -> HFA701LLHA2026-01-11 | C15: 46033 | D15: HFA701 | E15: SCD | G15: AT76 | H15: 4X-IHA | I15: ISR | J15: Haifa/U Michaeli | K15: LLHA | L15: HFA | M15: NEU | N15: GRC | O15: Athens Intl Eleftherios Venizelos | P15: LGAV | Q15: ATH | R15: EU | S15: 1157 | T15: 0 | U15: 0.12569444 | V15: 1360 | W15: 1740 | X15: 3100 | Y15: No | Z15: 1270 | AA15: 1830 | AB15: 0 | AC15: 0 | AD15: 0 | AE15: 0 | AG15: 0 | AH15: 0 | AI15: 0 | AJ15: 0 | AK15: 5.7828 | AL15: 5.7828 | AM15: 5.7828
A16: =CONCATENATE(D16,K16,TEXT(C16,"YYYY-MM-DD")) -> HFA702LGAV2026-01-11 | B16: =VLOOKUP(A16,Sheet1!A16:B1358,1,FALSE) -> HFA702LGAV2026-01-11 | C16: 46033 | D16: HFA702 | E16: SCD | G16: AT76 | H16: 4X-IHA | I16: GRC | J16: Athens Intl Eleftherios Venizelos | K16: LGAV | L16: ATH | M16: EU | N16: ISR | O16: Haifa/U Michaeli | P16: LLHA | Q16: HFA | R16: NEU | S16: 1157 | T16: 0 | U16: 0.10277778 | V16: 1270 | W16: 1630 | X16: 2900 | Y16: No | Z16: 1330 | AA16: 1570 | AB16: 0 | AC16: 0 | AD16: 0 | AE16: 0 | AG16: 0 | AH16: 0 | AI16: 0 | AJ16: 0 | AK16: 4.9612 | AL16: 4.9612 | AM16: 4.9612
A17: =CONCATENATE(D17,K17,TEXT(C17,"YYYY-MM-DD")) -> HFA605LLHA2026-01-11 | B17: =VLOOKUP(A17,Sheet1!A17:B1359,1,FALSE) -> HFA605LLHA2026-01-11 | C17: 46033 | D17: HFA605 | E17: SCD | F17: Both airfields outside EU | G17: AT76 | H17: 4X-IHA | I17: ISR | J17: Haifa/U Michaeli | K17: LLHA | L17: HFA | M17: NEU | N17: ISR | O17: Eilat/Ilan and Assaf Ramon Intl (Timna) | P17: LLER | Q17: ETM | R17: NEU | S17: 342 | T17: 0 | U17: 0.043055556 | V17: 1330 | W17: 380 | X17: 1710 | Y17: No | Z17: 950 | AA17: 760 | AB17: 0 | AC17: 0 | AD17: 0 | AE17: 0 | AG17: 0 | AH17: 0 | AI17: 0 | AJ17: 0 | AK17: 2.4016 | AL17: 2.4016 | AM17: 2.4016
A18: =CONCATENATE(D18,K18,TEXT(C18,"YYYY-MM-DD")) -> HFA606LLER2026-01-11 | B18: =VLOOKUP(A18,Sheet1!A18:B1360,1,FALSE) -> HFA606LLER2026-01-11 | C18: 46033 | D18: HFA606 | E18: SCD | F18: Both airfields outside EU | G18: AT76 | H18: 4X-IHA | I18: ISR | J18: Eilat/Ilan and Assaf Ramon Intl (Timna) | K18: LLER | L18: ETM | M18: NEU | N18: ISR | O18: Haifa/U Michaeli | P18: LLHA | Q18: HFA | R18: NEU | S18: 342 | T18: 0 | U18: 0.040277778 | V18: 950 | W18: 1750 | X18: 2700 | Y18: No | Z18: 2060 | AA18: 640 | AB18: 0 | AC18: 0 | AD18: 0 | AE18: 0 | AG18: 0 | AH18: 0 | AI18: 0 | AJ18: 0 | AK18: 2.0224 | AL18: 2.0224 | AM18: 2.0224
A19: =CONCATENATE(D19,K19,TEXT(C19,"YYYY-MM-DD")) -> HFA601LLHA2026-01-12 | B19: =VLOOKUP(A19,Sheet1!A19:B1361,1,FALSE) -> HFA601LLHA2026-01-12 | C19: 46034 | D19: HFA601 | E19: SCD | F19: Both airfields outside EU | G19: AT76 | H19: 4X-IHA | I19: ISR | J19: Haifa/U Michaeli | K19: LLHA | L19: HFA | M19: NEU | N19: ISR | O19: Eilat/Ilan and Assaf Ramon Intl (Timna) | P19: LLER | Q19: ETM | R19: NEU | S19: 342 | T19: 0 | U19: 0.047916667 | V19: 2060 | W19: 140 | X19: 2200 | Y19: No | Z19: 1520 | AA19: 680 | AB19: 0 | AC19: 0 | AD19: 0 | AE19: 0 | AG19: 0 | AH19: 0 | AI19: 0 | AJ19: 0 | AK19: 2.1488 | AL19: 2.1488 | AM19: 2.1488
A20: =CONCATENATE(D20,K20,TEXT(C20,"YYYY-MM-DD")) -> HFA602LLER2026-01-12 | B20: =VLOOKUP(A20,Sheet1!A20:B1362,1,FALSE) -> HFA602LLER2026-01-12 | C20: 46034 | D20: HFA602 | E20: SCD | F20: Both airfields outside EU | G20: AT76 | H20: 4X-IHA | I20: ISR | J20: Eilat/Ilan and Assaf Ramon Intl (Timna) | K20: LLER | L20: ETM | M20: NEU | N20: ISR | O20: Haifa/U Michaeli | P20: LLHA | Q20: HFA | R20: NEU | S20: 342 | T20: 0 | U20: 0.065972222 | V20: 1520 | W20: 880 | X20: 2400 | Y20: No | Z20: 1490 | AA20: 910 | AB20: 0 | AC20: 0 | AD20: 0 | AE20: 0 | AG20: 0 | AH20: 0 | AI20: 0 | AJ20: 0 | AK20: 2.8756 | AL20: 2.8756 | AM20: 2.8756
A21: =CONCATENATE(D21,K21,TEXT(C21,"YYYY-MM-DD")) -> HFA703LLHA2026-01-12 | B21: =VLOOKUP(A21,Sheet1!A21:B1363,1,FALSE) -> HFA703LLHA2026-01-12 | C21: 46034 | D21: HFA703 | E21: SCD | G21: AT76 | H21: 4X-IHA | I21: ISR | J21: Haifa/U Michaeli | K21: LLHA | L21: HFA | M21: NEU | N21: GRC | O21: Athens Intl Eleftherios Venizelos | P21: LGAV | Q21: ATH | R21: EU | S21: 1157 | T21: 0 | U21: 0.14513889 | V21: 1490 | W21: 1810 | X21: 3300 | Y21: No | Z21: 1630 | AA21: 1670 | AB21: 0 | AC21: 0 | AD21: 0 | AE21: 0 | AG21: 0 | AH21: 0 | AI21: 0 | AJ21: 0 | AK21: 5.2772 | AL21: 5.2772 | AM21: 5.2772
A22: =CONCATENATE(D22,K22,TEXT(C22,"YYYY-MM-DD")) -> HFA202LGAV2026-01-14 | B22: =VLOOKUP(A22,Sheet1!A22:B1364,1,FALSE) -> HFA202LGAV2026-01-14 | C22: 46036 | D22: HFA202 | E22: NSCD | G22: AT76 | H22: 4X-IHA | I22: GRC | J22: Athens Intl Eleftherios Venizelos | K22: LGAV | L22: ATH | M22: EU | N22: ISR | O22: Haifa/U Michaeli | P22: LLHA | Q22: HFA | R22: NEU | S22: 1157 | T22: 1158 | U22: 0.10069444 | V22: 1630 | W22: 1770 | X22: 3400 | Y22: No | Z22: 2220 | AA22: 1180 | AB22: 0 | AC22: 0 | AD22: 0 | AE22: 0 | AG22: 0 | AH22: 0 | AI22: 0 | AJ22: 0 | AK22: 3.7288 | AL22: 3.7288 | AM22: 3.7288
A23: =CONCATENATE(D23,K23,TEXT(C23,"YYYY-MM-DD")) -> HFA851LLHA2026-01-15 | B23: =VLOOKUP(A23,Sheet1!A23:B1365,1,FALSE) -> HFA851LLHA2026-01-15 | C23: 46037 | D23: HFA851 | E23: SCD | G23: AT76 | H23: 4X-IHA | I23: ISR | J23: Haifa/U Michaeli | K23: LLHA | L23: HFA | M23: NEU | N23: CYP | O23: Paphos International (Pafos) | P23: LCPH | Q23: PFO | R23: EU | S23: 318 | T23: 0 | U23: 0.042361111 | V23: 2220 | W23: 0 | X23: 2220 | Y23: No | Z23: 1630 | AA23: 590 | AB23: 0 | AC23: 0 | AD23: 0 | AE23: 0 | AG23: 0 | AH23: 0 | AI23: 0 | AJ23: 0 | AK23: 1.8644 | AL23: 1.8644 | AM23: 1.8644
A24: =CONCATENATE(D24,K24,TEXT(C24,"YYYY-MM-DD")) -> HFA852LCPH2026-01-15 | B24: =VLOOKUP(A24,Sheet1!A24:B1366,1,FALSE) -> HFA852LCPH2026-01-15 | C24: 46037 | D24: HFA852 | E24: SCD | G24: AT76 | H24: 4X-IHA | I24: CYP | J24: Paphos International (Pafos) | K24: LCPH | L24: PFO | M24: EU | N24: ISR | O24: Haifa/U Michaeli | P24: LLHA | Q24: HFA | R24: NEU | S24: 318 | T24: 0 | U24: 0.038888889 | V24: 1630 | W24: 870 | X24: 2500 | Y24: No | Z24: 1960 | AA24: 540 | AB24: 0 | AC24: 0 | AD24: 0 | AE24: 0 | AG24: 0 | AH24: 0 | AI24: 0 | AJ24: 0 | AK24: 1.7064 | AL24: 1.7064 | AM24: 1.7064
A25: =CONCATENATE(D25,K25,TEXT(C25,"YYYY-MM-DD")) -> HFA703LLHA2026-01-15 | B25: =VLOOKUP(A25,Sheet1!A25:B1367,1,FALSE) -> HFA703LLHA2026-01-15 | C25: 46037 | D25: HFA703 | E25: SCD | G25: AT76 | H25: 4X-IHA | I25: ISR | J25: Haifa/U Michaeli | K25: LLHA | L25: HFA | M25: NEU | N25: GRC | O25: Athens Intl Eleftherios Venizelos | P25: LGAV | Q25: ATH | R25: EU | S25: 1157 | T25: 0 | U25: 0.12777778 | V25: 1960 | W25: 1140 | X25: 3100 | Y25: No | Z25: 1190 | AA25: 1910 | AB25: 0 | AC25: 0 | AD25: 0 | AE25: 0 | AG25: 0 | AH25: 0 | AI25: 0 | AJ25: 0 | AK25: 6.0356 | AL25: 6.0356 | AM25: 6.0356
A26: =CONCATENATE(D26,K26,TEXT(C26,"YYYY-MM-DD")) -> HFA704LGAV2026-01-15 | B26: =VLOOKUP(A26,Sheet1!A26:B1368,1,FALSE) -> HFA704LGAV2026-01-15 | C26: 46037 | D26: HFA704 | E26: SCD | G26: AT76 | H26: 4X-IHA | I26: GRC | J26: Athens Intl Eleftherios Venizelos | K26: LGAV | L26: ATH | M26: EU | N26: ISR | O26: Haifa/U Michaeli | P26: LLHA | Q26: HFA | R26: NEU | S26: 1157 | T26: 0 | U26: 0.10486111 | V26: 1190 | W26: 2310 | X26: 3500 | Y26: No | Z26: 2070 | AA26: 1430 | AB26: 0 | AC26: 0 | AD26: 0 | AE26: 0 | AG26: 0 | AH26: 0 | AI26: 0 | AJ26: 0 | AK26: 4.5188 | AL26: 4.5188 | AM26: 4.5188
A27: =CONCATENATE(D27,K27,TEXT(C27,"YYYY-MM-DD")) -> HFA701LLHA2026-01-16 | B27: =VLOOKUP(A27,Sheet1!A27:B1369,1,FALSE) -> HFA701LLHA2026-01-16 | C27: 46038 | D27: HFA701 | E27: SCD | G27: AT76 | H27: 4X-IHA | I27: ISR | J27: Haifa/U Michaeli | K27: LLHA | L27: HFA | M27: NEU | N27: GRC | O27: Athens Intl Eleftherios Venizelos | P27: LGAV | Q27: ATH | R27: EU | S27: 1157 | T27: 0 | U27: 0.12361111 | V27: 2070 | W27: 1130 | X27: 3200 | Y27: No | Z27: 1370 | AA27: 1830 | AB27: 0 | AC27: 0 | AD27: 0 | AE27: 0 | AG27: 0 | AH27: 0 | AI27: 0 | AJ27: 0 | AK27: 5.7828 | AL27: 5.7828 | AM27: 5.7828
A28: =CONCATENATE(D28,K28,TEXT(C28,"YYYY-MM-DD")) -> HFA702LGAV2026-01-16 | B28: =VLOOKUP(A28,Sheet1!A28:B1370,1,FALSE) -> HFA702LGAV2026-01-16 | C28: 46038 | D28: HFA702 | E28: SCD | G28: AT76 | H28: 4X-IHA | I28: GRC | J28: Athens Intl Eleftherios Venizelos | K28: LGAV | L28: ATH | M28: EU | N28: ISR | O28: Haifa/U Michaeli | P28: LLHA | Q28: HFA | R28: NEU | S28: 1157 | T28: 0 | U28: 0.10208333 | V28: 1370 | W28: 2030 | X28: 3400 | Y28: No | Z28: 2080 | AA28: 1320 | AB28: 0 | AC28: 0 | AD28: 0 | AE28: 0 | AG28: 0 | AH28: 0 | AI28: 0 | AJ28: 0 | AK28: 4.1712 | AL28: 4.1712 | AM28: 4.1712
A29: =CONCATENATE(D29,K29,TEXT(C29,"YYYY-MM-DD")) -> HFA701LLHA2026-01-18 | B29: =VLOOKUP(A29,Sheet1!A29:B1371,1,FALSE) -> HFA701LLHA2026-01-18 | C29: 46040 | D29: HFA701 | E29: SCD | G29: AT76 | H29: 4X-IHA | I29: ISR | J29: Haifa/U Michaeli | K29: LLHA | L29: HFA | M29: NEU | N29: GRC | O29: Athens Intl Eleftherios Venizelos | P29: LGAV | Q29: ATH | R29: EU | S29: 1157 | T29: 0 | U29: 0.12777778 | V29: 2080 | W29: 1120 | X29: 3200 | Y29: No | Z29: 1340 | AA29: 1860 | AB29: 0 | AC29: 0 | AD29: 0 | AE29: 0 | AG29: 0 | AH29: 0 | AI29: 0 | AJ29: 0 | AK29: 5.8776 | AL29: 5.8776 | AM29: 5.8776
A30: =CONCATENATE(D30,K30,TEXT(C30,"YYYY-MM-DD")) -> HFA702LGAV2026-01-18 | B30: =VLOOKUP(A30,Sheet1!A30:B1372,1,FALSE) -> HFA702LGAV2026-01-18 | C30: 46040 | D30: HFA702 | E30: SCD | G30: AT76 | H30: 4X-IHA | I30: GRC | J30: Athens Intl Eleftherios Venizelos | K30: LGAV | L30: ATH | M30: EU | N30: ISR | O30: Haifa/U Michaeli | P30: LLHA | Q30: HFA | R30: NEU | S30: 1157 | T30: 0 | U30: 0.10763889 | V30: 1340 | W30: 1560 | X30: 2900 | Y30: No | Z30: 1410 | AA30: 1490 | AB30: 0 | AC30: 0 | AD30: 0 | AE30: 0 | AG30: 0 | AH30: 0 | AI30: 0 | AJ30: 0 | AK30: 4.7084 | AL30: 4.7084 | AM30: 4.7084
A31: =CONCATENATE(D31,K31,TEXT(C31,"YYYY-MM-DD")) -> HFA601LLHA2026-01-19 | B31: =VLOOKUP(A31,Sheet1!A31:B1373,1,FALSE) -> HFA601LLHA2026-01-19 | C31: 46041 | D31: HFA601 | E31: SCD | F31: Both airfields outside EU | G31: AT76 | H31: 4X-IHA | I31: ISR | J31: Haifa/U Michaeli | K31: LLHA | L31: HFA | M31: NEU | N31: ISR | O31: Eilat/Ilan and Assaf Ramon Intl (Timna) | P31: LLER | Q31: ETM | R31: NEU | S31: 342 | T31: 0 | U31: 0.044444444 | V31: 1410 | W31: 390 | X31: 1800 | Y31: No | Z31: 1150 | AA31: 650 | AB31: 0 | AC31: 0 | AD31: 0 | AE31: 0 | AG31: 0 | AH31: 0 | AI31: 0 | AJ31: 0 | AK31: 2.054 | AL31: 2.054 | AM31: 2.054
A32: =CONCATENATE(D32,K32,TEXT(C32,"YYYY-MM-DD")) -> HFA602LLER2026-01-19 | B32: =VLOOKUP(A32,Sheet1!A32:B1374,1,FALSE) -> HFA602LLER2026-01-19 | C32: 46041 | D32: HFA602 | E32: SCD | F32: Both airfields outside EU | G32: AT76 | H32: 4X-IHA | I32: ISR | J32: Eilat/Ilan and Assaf Ramon Intl (Timna) | K32: LLER | L32: ETM | M32: NEU | N32: ISR | O32: Haifa/U Michaeli | P32: LLHA | Q32: HFA | R32: NEU | S32: 342 | T32: 0 | U32: 0.042361111 | V32: 1150 | W32: 1350 | X32: 2500 | Y32: No | Z32: 1790 | AA32: 710 | AB32: 0 | AC32: 0 | AD32: 0 | AE32: 0 | AG32: 0 | AH32: 0 | AI32: 0 | AJ32: 0 | AK32: 2.2436 | AL32: 2.2436 | AM32: 2.2436
A33: =CONCATENATE(D33,K33,TEXT(C33,"YYYY-MM-DD")) -> HFA701LLHA2026-01-21 | B33: =VLOOKUP(A33,Sheet1!A33:B1375,1,FALSE) -> HFA701LLHA2026-01-21 | C33: 46043 | D33: HFA701 | E33: SCD | G33: AT76 | H33: 4X-IHA | I33: ISR | J33: Haifa/U Michaeli | K33: LLHA | L33: HFA | M33: NEU | N33: GRC | O33: Athens Intl Eleftherios Venizelos | P33: LGAV | Q33: ATH | R33: EU | S33: 1157 | T33: 0 | U33: 0.11666667 | V33: 1790 | W33: 1910 | X33: 3700 | Y33: No | Z33: 1810 | AA33: 1890 | AB33: 0 | AC33: 0 | AD33: 0 | AE33: 0 | AG33: 0 | AH33: 0 | AI33: 0 | AJ33: 0 | AK33: 5.9724 | AL33: 5.9724 | AM33: 5.9724
A34: =CONCATENATE(D34,K34,TEXT(C34,"YYYY-MM-DD")) -> HFA702LGAV2026-01-21 | B34: =VLOOKUP(A34,Sheet1!A34:B1376,1,FALSE) -> HFA702LGAV2026-01-21 | C34: 46043 | D34: HFA702 | E34: SCD | G34: AT76 | H34: 4X-IHA | I34: GRC | J34: Athens Intl Eleftherios Venizelos | K34: LGAV | L34: ATH | M34: EU | N34: ISR | O34: Haifa/U Michaeli | P34: LLHA | Q34: HFA | R34: NEU | S34: 1157 | T34: 0 | U34: 0.10277778 | V34: 1810 | W34: 2690 | X34: 4500 | Y34: No | Z34: 2950 | AA34: 1550 | AB34: 0 | AC34: 0 | AD34: 0 | AE34: 0 | AG34: 0 | AH34: 0 | AI34: 0 | AJ34: 0 | AK34: 4.898 | AL34: 4.898 | AM34: 4.898
A35: =CONCATENATE(D35,K35,TEXT(C35,"YYYY-MM-DD")) -> HFA703LLHA2026-01-21 | B35: =VLOOKUP(A35,Sheet1!A35:B1377,1,FALSE) -> HFA703LLHA2026-01-21 | C35: 46043 | D35: HFA703 | E35: SCD | G35: AT76 | H35: 4X-IHA | I35: ISR | J35: Haifa/U Michaeli | K35: LLHA | L35: HFA | M35: NEU | N35: GRC | O35: Athens Intl Eleftherios Venizelos | P35: LGAV | Q35: ATH | R35: EU | S35: 1157 | T35: 0 | U35: 0.12708333 | V35: 2950 | W35: 750 | X35: 3700 | Y35: No | Z35: 1770 | AA35: 1930 | AB35: 0 | AC35: 0 | AD35: 0 | AE35: 0 | AG35: 0 | AH35: 0 | AI35: 0 | AJ35: 0 | AK35: 6.0988 | AL35: 6.0988 | AM35: 6.0988
A36: =CONCATENATE(D36,K36,TEXT(C36,"YYYY-MM-DD")) -> HFA704LGAV2026-01-21 | B36: =VLOOKUP(A36,Sheet1!A36:B1378,1,FALSE) -> HFA704LGAV2026-01-21 | C36: 46043 | D36: HFA704 | E36: SCD | G36: AT76 | H36: 4X-IHA | I36: GRC | J36: Athens Intl Eleftherios Venizelos | K36: LGAV | L36: ATH | M36: EU | N36: ISR | O36: Haifa/U Michaeli | P36: LLHA | Q36: HFA | R36: NEU | S36: 1157 | T36: 0 | U36: 0.10555556 | V36: 1770 | W36: 1530 | X36: 3300 | Y36: No | Z36: 1750 | AA36: 1550 | AB36: 0 | AC36: 0 | AD36: 0 | AE36: 0 | AG36: 0 | AH36: 0 | AI36: 0 | AJ36: 0 | AK36: 4.898 | AL36: 4.898 | AM36: 4.898
A37: =CONCATENATE(D37,K37,TEXT(C37,"YYYY-MM-DD")) -> HFA703LLHA2026-01-22 | B37: =VLOOKUP(A37,Sheet1!A37:B1379,1,FALSE) -> HFA703LLHA2026-01-22 | C37: 46044 | D37: HFA703 | E37: SCD | G37: AT76 | H37: 4X-IHA | I37: ISR | J37: Haifa/U Michaeli | K37: LLHA | L37: HFA | M37: NEU | N37: GRC | O37: Athens Intl Eleftherios Venizelos | P37: LGAV | Q37: ATH | R37: EU | S37: 1157 | T37: 0 | U37: 0.12430556 | V37: 1750 | W37: 1550 | X37: 3300 | Y37: No | Z37: 1500 | AA37: 1800 | AB37: 0 | AC37: 0 | AD37: 0 | AE37: 0 | AG37: 0 | AH37: 0 | AI37: 0 | AJ37: 0 | AK37: 5.688 | AL37: 5.688 | AM37: 5.688
A38: =CONCATENATE(D38,K38,TEXT(C38,"YYYY-MM-DD")) -> HFA704LGAV2026-01-22 | B38: =VLOOKUP(A38,Sheet1!A38:B1380,1,FALSE) -> HFA704LGAV2026-01-22 | C38: 46044 | D38: HFA704 | E38: SCD | G38: AT76 | H38: 4X-IHA | I38: GRC | J38: Athens Intl Eleftherios Venizelos | K38: LGAV | L38: ATH | M38: EU | N38: ISR | O38: Haifa/U Michaeli | P38: LLHA | Q38: HFA | R38: NEU | S38: 1157 | T38: 0 | U38: 0.11319444 | V38: 1500 | W38: 1800 | X38: 3300 | Y38: No | Z38: 1930 | AA38: 1370 | AB38: 0 | AC38: 0 | AD38: 0 | AE38: 0 | AG38: 0 | AH38: 0 | AI38: 0 | AJ38: 0 | AK38: 4.3292 | AL38: 4.3292 | AM38: 4.3292
A39: =CONCATENATE(D39,K39,TEXT(C39,"YYYY-MM-DD")) -> HFA701LLHA2026-01-23 | B39: =VLOOKUP(A39,Sheet1!A39:B1381,1,FALSE) -> HFA701LLHA2026-01-23 | C39: 46045 | D39: HFA701 | E39: SCD | G39: AT76 | H39: 4X-IHA | I39: ISR | J39: Haifa/U Michaeli | K39: LLHA | L39: HFA | M39: NEU | N39: GRC | O39: Athens Intl Eleftherios Venizelos | P39: LGAV | Q39: ATH | R39: EU | S39: 1157 | T39: 0 | U39: 0.12430556 | V39: 1930 | W39: 1270 | X39: 3200 | Y39: No | Z39: 1420 | AA39: 1780 | AB39: 0 | AC39: 0 | AD39: 0 | AE39: 0 | AG39: 0 | AH39: 0 | AI39: 0 | AJ39: 0 | AK39: 5.6248 | AL39: 5.6248 | AM39: 5.6248
A40: =CONCATENATE(D40,K40,TEXT(C40,"YYYY-MM-DD")) -> HFA702LGAV2026-01-23 | B40: =VLOOKUP(A40,Sheet1!A40:B1382,1,FALSE) -> HFA702LGAV2026-01-23 | C40: 46045 | D40: HFA702 | E40: SCD | G40: AT76 | H40: 4X-IHA | I40: GRC | J40: Athens Intl Eleftherios Venizelos | K40: LGAV | L40: ATH | M40: EU | N40: ISR | O40: Haifa/U Michaeli | P40: LLHA | Q40: HFA | R40: NEU | S40: 1157 | T40: 0 | U40: 0.10347222 | V40: 1420 | W40: 1780 | X40: 3200 | Y40: No | Z40: 1910 | AA40: 1290 | AB40: 0 | AC40: 0 | AD40: 0 | AE40: 0 | AG40: 0 | AH40: 0 | AI40: 0 | AJ40: 0 | AK40: 4.0764 | AL40: 4.0764 | AM40: 4.0764
...

Sheet Sheet1
A1: key | B1: flightid | C1: releasestatus | D1: filing_status | E1: departure | F1: destination | G1: scheduled_time_of_departure | H1: aircraft_registration | I1: callsign | J1: alternate | K1: flight_rule | L1: atc_type_of_flight | M1: dispatcher_notes | N1: item18_remarks | O1: route_to_destination | P1: route_altitude_fl | Q1: load_people | R1: load_cargo_kg | S1: log_time_off | T1: log_time_on | U1: log_flight_duration | V1: log_block_duration | W1: perf_flight_fuel | X1: perf_taxi_fuel | Y1: perf_fuel_to_destination | Z1: perf_landing_fuel | AA1: perf_alternate_fuel | AB1: perf_reserve_fuel | AC1: perf_extra_fuel | AD1: perf_contingency_fuel | AE1: perf_total_fuel | AF1: perf_max_total_fuel | AG1: perf_co2_emission | AH1: perf_taxi_time_min | AI1: perf_time_to_dest_min | AJ1: perf_total_time_min | AK1: perf_departure_time_utc | AL1: perf_estimated_arrival_utc | AM1: dist_destination_nm | AN1: dist_gcd_destination_nm | AO1: dist_alternate_nm | AP1: weight_ramp | AQ1: weight_takeoff | AR1: weight_max_takeoff | AS1: weight_zero_fuel | AT1: weight_landing | AU1: weather_avg_wind_comp | AV1: weather_avg_wind_dir | AW1: weather_avg_wind_vel | AX1: weather_avg_isa_dev | AY1: is_etops_enabled
A2: =CONCATENATE(I2,E2,LEFT(G2,10)) -> HFA101LLBG2026-03-04 | B2: 9f12e41e0dad4d44adf26921a65ffb29 | C2: NotReleased | D2: None | E2: LLBG | F2: LCLK | G2: 2026-03-04T14:30:00Z | H2: 4XIHC | I2: HFA101 | J2: LCPH | K2: IFR | L2: G | O2: SUVAS DCT STEPA DCT APLON A28 BETID | P2: 140 | Q2: 0 | R2: 500 | W2: 1007 | X2: 80 | Y2: 927 | Z2: 643 | AA2: 323 | AB2: 231 | AC2: 42 | AD2: 46 | AE2: 1650 | AF2: 5000 | AG2: 3183 | AH2: 0 | AI2: 73 | AJ2: 133 | AK2: 2026-03-04T14:30:00Z | AL2: 2026-03-04T15:43:21.480904Z | AM2: 299.85 | AN2: 183.03 | AO2: 73.5 | AP2: 15650 | AQ2: 15570 | AR2: 23000 | AS2: 14000 | AT2: 14643 | AU2: -17 | AV2: 334.87 | AW2: 23.67 | AX2: 2.13 | AY2: FALSE
A3: =CONCATENATE(I3,E3,LEFT(G3,10)) -> HFA101LLBG2026-03-05 | B3: 1355c4b7243641c49127b032148ebe39 | C3: Success | D3: Filed | E3: LLBG | F3: LCLK | G3: 2026-03-05T14:25:00Z | H3: 4XIHC | I3: HFA101 | J3: LCPH | K3: IFR | L3: G | M3: 1. EXTRA FUEL IS DUE EST FUE ON BOARD. 2/EXTRA FUEL POLICY WAS OVERRIDDEN BY LIOR YAVOR. DISP-EREZ Y. | N3: RTECOORATC LCCC | O3: SUVAS STEPA APLON A28 BETID | P3: 160 | Q3: 4 | R3: 700 | S3: 2026-03-05T15:50:40Z | T3: 2026-03-05T16:55:02Z | U3: 1.0727778 | V3: 1.53 | W3: 950 | X3: 80 | Y3: 870 | Z3: 697 | AA3: 321 | AB3: 233 | AC3: 100 | AD3: 44 | AE3: 1647 | AF3: 5000 | AG3: 3002 | AH3: 0 | AI3: 72 | AJ3: 136 | AK3: 2026-03-05T14:25:00Z | AL3: 2026-03-05T15:37:04.4575967Z | AM3: 299.85 | AN3: 183.03 | AO3: 73.5 | AP3: 15847 | AQ3: 15767 | AR3: 23000 | AS3: 14200 | AT3: 14897 | AU3: -8 | AV3: 301.59 | AW3: 18.41 | AX3: 1.7 | AY3: FALSE
A4: =CONCATENATE(I4,E4,LEFT(G4,10)) -> HFA102LCLK2026-03-05 | B4: 60455fdc720546a2a3a8f7f4d8daab26 | C4: Success | D4: Filed | E4: LCLK | F4: LLBG | G4: 2026-03-05T12:45:00Z | H4: 4XIHC | I4: HFA102 | J4: LCLK | K4: IFR | L4: S | M4: 1. THIS FLIGHT WAS PREPARED BY NIMROD R. 2. EXTRA FUEL PLANNED FOR THE NEXT LEG. | N4: RTECOORATC LCCC | O4: EMEDA2B EMEDA M67 ANANE DCT IDAKU DCT PIKOG L609 ZUKKO | P4: 130 | Q4: 2 | R4: 7000 | S4: 2026-03-05T13:22:34Z | T4: 2026-03-05T14:20:01Z | U4: 0.9575 | V4: 1.2302778 | W4: 894 | X4: 80 | Y4: 814 | Z4: 1606 | AA4: 986 | AB4: 293 | AC4: 278 | AD4: 49 | AE4: 2500 | AF4: 5000 | AG4: 2826 | AH4: 0 | AI4: 63 | AJ4: 193 | AK4: 2026-03-05T12:45:00Z | AL4: 2026-03-05T13:47:55.7023105Z | AM4: 264.72 | AN4: 183.03 | AO4: 299.85 | AP4: 23000 | AQ4: 22920 | AR4: 23000 | AS4: 20500 | AT4: 22106 | AU4: 7 | AV4: 307.76 | AW4: 12.44 | AX4: 2.28 | AY4: FALSE
A5: =CONCATENATE(I5,E5,LEFT(G5,10)) -> HFA102LCLK2026-03-29 | B5: 1208ea5514a04d80a29d00daacec2307 | C5: Success | D5: Filed | E5: LCLK | F5: LLBG | G5: 2026-03-29T10:45:00Z | H5: 4XIHE | I5: HFA102 | J5: LCLK | K5: IFR | L5: S | M5: 1. THIS FLIGHT WAS PREPARED BY NIMROD R. EXTRA FUEL PLANNED FOR POSSIBLE SIRENS. | O5: EMEDA2B EMEDA M67 ANANE DCT IDAKU DCT PIKOG L609 ZUKKO AMMOS1A | P5: 150 | Q5: 2 | R5: 7000 | S5: 2026-03-29T10:58:58Z | T5: 2026-03-29T11:58:29Z | U5: 0.99194444 | V5: 1.2538889 | W5: 947 | X5: 80 | Y5: 867 | Z5: 1653 | AA5: 997 | AB5: 292 | AC5: 315 | AD5: 49 | AE5: 2600 | AF5: 5000 | AG5: 2992 | AH5: 0 | AI5: 69 | AJ5: 211 | AK5: 2026-03-29T10:45:00Z | AL5: 2026-03-29T11:54:22.4837397Z | AM5: 278.31 | AN5: 183.03 | AO5: 300.19 | AP5: 22925 | AQ5: 22845 | AR5: 23000 | AS5: 20325 | AT5: 21978 | AU5: -4 | AV5: 249.7 | AW5: 51.93 | AX5: 0.74 | AY5: FALSE
A6: =CONCATENATE(I6,E6,LEFT(G6,10)) -> HFA103LLBG2026-03-05 | B6: ca25baac07cc4a47ba3b5e8a77e815e4 | C6: Success | D6: Filed | E6: LLBG | F6: LCLK | G6: 2026-03-05T15:25:00Z | H6: 4XIHE | I6: HFA103 | J6: LCPH | K6: IFR | L6: S | M6: 1. THIS FLIGHT WAS PREPARED BY NIMROD R. | N6: RTECOORATC LCCC | O6: SUVAS DCT STEPA DCT APLON A28 BETID | P6: 160 | Q6: 3 | R6: 700 | S6: 2026-03-05T16:12:48Z | T6: 2026-03-05T17:15:21Z | U6: 1.0425 | V6: 1.3227778 | W6: 929 | X6: 80 | Y6: 849 | Z6: 690 | AA6: 315 | AB6: 232 | AC6: 100 | AD6: 42 | AE6: 1619 | AF6: 5000 | AG6: 2936 | AH6: 0 | AI6: 72 | AJ6: 136 | AK6: 2026-03-05T15:25:00Z | AL6: 2026-03-05T16:37:01.4169716Z | AM6: 299.85 | AN6: 183.03 | AO6: 73.5 | AP6: 15644 | AQ6: 15564 | AR6: 23000 | AS6: 14025 | AT6: 14715 | AU6: -8 | AV6: 302.48 | AW6: 18.9 | AX6: 1.7 | AY6: FALSE
A7: =CONCATENATE(I7,E7,LEFT(G7,10)) -> HFA104LCLK2026-03-05 | B7: 38eae647f5394118b67a9ba305a74076 | C7: Success | D7: Filed | E7: LCLK | F7: LLBG | G7: 2026-03-05T13:45:00Z | H7: 4XIHE | I7: HFA104 | J7: LCLK | K7: IFR | L7: S | M7: **NEW OFP DUE DROP OF ZFW BY MORE THE 800 KG 1. DISP EREZ Y. 2. EXTRA FUEL PLANNED FOR THE NEXT LEG. | N7: RTECOORATC LCCC | O7: EMEDA2B EMEDA DCT ANANE DCT IDAKU DCT PIKOG L609 ZUKKO | P7: 130 | Q7: 2 | R7: 0 | S7: 2026-03-05T11:27:52Z | T7: 2026-03-05T15:26:21Z | U7: 3.9747222 | V7: 1.2980556 | W7: 863 | X7: 80 | Y7: 783 | Z7: 1637 | AA7: 950 | AB7: 278 | AC7: 363 | AD7: 46 | AE7: 2500 | AF7: 5000 | AG7: 2727 | AH7: 0 | AI7: 62 | AJ7: 198 | AK7: 2026-03-05T13:45:00Z | AL7: 2026-03-05T14:47:14.5552237Z | AM7: 264.72 | AN7: 183.03 | AO7: 299.85 | AP7: 21494 | AQ7: 21414 | AR7: 23000 | AS7: 18994 | AT7: 20631 | AU7: 7 | AV7: 304.82 | AW7: 12.32 | AX7: 2.19 | AY7: FALSE
A8: =CONCATENATE(I8,E8,LEFT(G8,10)) -> HFA104LCLK2026-03-30 | B8: 8655234f0e404e90ae8cde9764e751ea | C8: Success | D8: Filed | E8: LCLK | F8: LLBG | G8: 2026-03-30T15:45:00Z | H8: 4XIHA | I8: HFA104 | J8: LCLK | K8: IFR | L8: S | M8: EXTRA FUEL IS FOR THE NEXT FLT AND CAN BE USED IF NEEDED DUE POSS HOLD. DISP-EREZ Y. | N8: DISPATCH +972502126365 | O8: EMEDA2B EMEDA M67 ANANE DCT IDAKU DCT PIKOG L609 ZUKKO AMMOS1A | P8: 150 | Q8: 2 | R8: 2700 | S8: 2026-03-30T16:17:58Z | T8: 2026-03-30T17:10:04Z | U8: 0.86833333 | V8: 1.1127778 | W8: 877 | X8: 80 | Y8: 797 | Z8: 1923 | AA8: 949 | AB8: 254 | AC8: 678 | AD8: 42 | AE8: 2800 | AF8: 5000 | AG8: 2770 | AH8: 0 | AI8: 65 | AJ8: 234 | AK8: 2026-03-30T15:45:00Z | AL8: 2026-03-30T16:49:43.6814202Z | AM8: 278.31 | AN8: 183.03 | AO8: 300.19 | AP8: 18705 | AQ8: 18625 | AR8: 23000 | AS8: 15905 | AT8: 17828 | AU8: 9 | AV8: 283.97 | AW8: 44.58 | AX8: 2.76 | AY8: FALSE
A9: =CONCATENATE(I9,E9,LEFT(G9,10)) -> HFA104LCLK2026-03-31 | B9: 18d8a77c3d4d4026808cce8385488b57 | C9: Success | D9: Filed | E9: LCLK | F9: LLBG | G9: 2026-03-31T15:45:00Z | H9: 4XIHC | I9: HFA104 | J9: LCLK | K9: IFR | L9: S | M9: EXTRA FUEL IS FOR THE NEXT FLIGHT DIS. BY AYELET W. | O9: N0274F150 EMEDA2B EMEDA M67 ANANE DCT IDAKU DCT PIKOG L609 ZUKKO AMMOS1A | P9: 150 | Q9: 4 | R9: 2500 | S9: 2026-03-31T16:03:52Z | T9: 2026-03-31T16:57:48Z | U9: 0.89888889 | V9: 1.1913889 | W9: 899 | X9: 80 | Y9: 819 | Z9: 1901 | AA9: 942 | AB9: 255 | AC9: 662 | AD9: 42 | AE9: 2800 | AF9: 5000 | AG9: 2842 | AH9: 0 | AI9: 67 | AJ9: 233 | AK9: 2026-03-31T15:45:00Z | AL9: 2026-03-31T16:51:35.7420566Z | AM9: 278.31 | AN9: 183.03 | AO9: 300.19 | AP9: 18800 | AQ9: 18720 | AR9: 23000 | AS9: 16000 | AT9: 17901 | AU9: 2 | AV9: 265.37 | AW9: 34.52 | AX9: 5.5 | AY9: FALSE
A10: =CONCATENATE(I10,E10,LEFT(G10,10)) -> HFA105LLBG2026-03-06 | B10: 247ade7c105f4155a29efc8d6ba07191 | C10: Success | D10: Filed | E10: LLBG | F10: LCLK | G10: 2026-03-06T19:40:00Z | H10: 4XIHC | I10: HFA105 | J10: LCPH | K10: IFR | L10: S | M10: 1. THIS FLIGHT WAS PREPARED BY NIMROD R. | N10: RTECOORATC LCCC | O10: N0282A160 SUVAS DCT STEPA DCT APLON A28 BETID | P10: 160 | Q10: 3 | R10: 700 | S10: 2026-03-06T20:22:29Z | T10: 2026-03-06T21:19:20Z | U10: 0.9475 | V10: 1.6930556 | W10: 982 | X10: 80 | Y10: 902 | Z10: 603 | AA10: 326 | AB10: 232 | AC10: 0 | AD10: 45 | AE10: 1585 | AF10: 5000 | AG10: 3103 | AH10: 0 | AI10: 75 | AJ10: 131 | AK10: 2026-03-06T19:40:00Z | AL10: 2026-03-06T20:55:05.2998591Z | AM10: 299.85 | AN10: 183.03 | AO10: 73.5 | AP10: 15785 | AQ10: 15705 | AR10: 23000 | AS10: 14200 | AT10: 14803 | AU10: -19 | AV10: 299.29 | AW10: 27.12 | AX10: 2.14 | AY10: FALSE
A11: =CONCATENATE(I11,E11,LEFT(G11,10)) -> HFA105LLBG2026-03-30 | B11: 185a145f782443aa9a20b966be943fbe | C11: Success | D11: Filed | E11: LLBG | F11: LCLK | G11: 2026-03-30T18:00:00Z | H11: 4XIHE | I11: HFA105 | J11: LCPH | K11: IFR | L11: S | M11: 1.EXTRA FUEL IS FOR POSS TAXI HOLD. 2.DTA NOT AVAIL FOR ISRAELI SIG MAPS. 3.FLT DISPATCHED AT F/L 160,AT F/L 120 IT IS 2 MIN SHORTER PER YOUR DISCRETION. DISP-EREZ Y. | O11: N0273A160 SUVAS1E SUVAS DCT STEPA DCT APLON A28 ANANE M28 BETID BETID1A | P11: 160 | Q11: 2 | R11: 6100 | S11: 2026-03-30T19:05:19Z | T11: 2026-03-30T20:27:32Z | U11: 1.3702778 | V11: 1.5869444 | W11: 1008 | X11: 80 | Y11: 928 | Z11: 968 | AA11: 345 | AB11: 277 | AC11: 300 | AD11: 46 | AE11: 1975 | AF11: 5000 | AG11: 3184 | AH11: 0 | AI11: 78 | AJ11: 161 | AK11: 2026-03-30T18:00:00Z | AL11: 2026-03-30T19:18:25.1697964Z | AM11: 301.74 | AN11: 183.03 | AO11: 73.5 | AP11: 21400 | AQ11: 21320 | AR11: 23000 | AS11: 19425 | AT11: 20393 | AU11: -18 | AV11: 283.4 | AW11: 42.83 | AX11: 4.23 | AY11: FALSE
A12: =CONCATENATE(I12,E12,LEFT(G12,10)) -> HFA105LLBG2026-03-31 | B12: 8c9740d1aa1941a58f75bb8091859dcf | C12: Success | D12: Filed | E12: LLBG | F12: LCLK | G12: 2026-03-31T18:00:00Z | H12: 4XIHC | I12: HFA105 | J12: LCPH | K12: IFR | L12: S | M12: EXTRA FUEL FOR POSS WAIT AT LLBG DIS. BY AYELET W. | N12: RTECOORATC | O12: N0273A160 SUVAS1E SUVAS DCT STEPA DCT APLON A28 ANANE M28 BETID BETID1A | P12: 160 | Q12: 3 | R12: 6200 | S12: 2026-03-31T18:14:28Z | T12: 2026-03-31T19:11:42Z | U12: 0.95388889 | V12: 1.4280556 | W12: 1021 | X12: 80 | Y12: 941 | Z12: 966 | AA12: 340 | AB12: 279 | AC12: 300 | AD12: 47 | AE12: 1987 | AF12: 5000 | AG12: 3227 | AH12: 0 | AI12: 79 | AJ12: 160 | AK12: 2026-03-31T18:00:00Z | AL12: 2026-03-31T19:18:43.8743292Z | AM12: 301.74 | AN12: 183.03 | AO12: 73.5 | AP12: 21687 | AQ12: 21607 | AR12: 23000 | AS12: 19700 | AT12: 20666 | AU12: -17 | AV12: 276.81 | AW12: 47.52 | AX12: 5.8 | AY12: FALSE
A13: =CONCATENATE(I13,E13,LEFT(G13,10)) -> HFA106LCLK2026-03-06 | B13: 80d314e8feb34e26ba6faf8f719eeacb | C13: Success | D13: Filed | E13: LCLK | F13: LLBG | G13: 2026-03-06T16:15:00Z | H13: 4XIHC | I13: HFA106 | J13: LCLK | K13: IFR | L13: S | M13: AC IS FUELED WITH 2500 KG EXTRA FUEL FOR THE NEXT LEG. DIS. BY NIMROD R. NEW OFP REV. 01 ISSUED DUE TO DECREASE IN ZFW. | O13: EMEDA2B EMEDA M67 ANANE DCT IDAKU DCT PIKOG L609 ZUKKO GODED2 | P13: 150 | Q13: 2 | R13: 0 | S13: 2026-03-06T16:33:08Z | T13: 2026-03-06T17:53:02Z | U13: 1.3316667 | V13: 1.6272222 | W13: 864 | X13: 80 | Y13: 784 | Z13: 1636 | AA13: 759 | AB13: 281 | AC13: 549 | AD13: 47 | AE13: 2500 | AF13: 5000 | AG13: 2730 | AH13: 0 | AI13: 61 | AJ13: 199 | AK13: 2026-03-06T16:15:00Z | AL13: 2026-03-06T17:16:25.3635947Z | AM13: 264.92 | AN13: 183.03 | AO13: 215.32 | AP13: 21781 | AQ13: 21701 | AR13: 23000 | AS13: 19281 | AT13: 20917 | AU13: 12 | AV13: 300.29 | AW13: 26.28 | AX13: 0.69 | AY13: FALSE
A14: =CONCATENATE(I14,E14,LEFT(G14,10)) -> HFA107LLBG2026-03-06 | B14: 5219ee7f3ae14bd6a29ab00d4f74a9a5 | C14: Success | D14: Filed | E14: LLBG | F14: LCLK | G14: 2026-03-06T16:41:00Z | H14: 4XIHE | I14: HFA107 | J14: LCPH | K14: IFR | L14: S | M14: EXTRA FUEL IS PER COMPANY POLICY. DIS BY AYELET | N14: RTECOORATC LCCC | O14: SUVAS STEPA APLON A28 BETID | P14: 160 | Q14: 4 | R14: 900 | S14: 2026-03-06T16:52:46Z | T14: 2026-03-06T17:51:21Z | U14: 0.97638889 | V14: 1.3327778 | W14: 974 | X14: 80 | Y14: 894 | Z14: 699 | AA14: 321 | AB14: 233 | AC14: 100 | AD14: 45 | AE14: 1672 | AF14: 5000 | AG14: 3077 | AH14: 0 | AI14: 76 | AJ14: 141 | AK14: 2026-03-06T16:41:00Z | AL14: 2026-03-06T17:57:07.2299126Z | AM14: 299.85 | AN14: 183.03 | AO14: 73.5 | AP14: 15897 | AQ14: 15817 | AR14: 23000 | AS14: 14225 | AT14: 14924 | AU14: -23 | AV14: 295.46 | AW14: 31.62 | AX14: 1.94 | AY14: FALSE
A15: =CONCATENATE(I15,E15,LEFT(G15,10)) -> HFA107LLBG2026-03-29 | B15: 220b920abb164023a73853b9af5659ca | C15: Success | D15: Filed | E15: LLBG | F15: LCLK | G15: 2026-03-29T13:10:00Z | H15: 4XIHE | I15: HFA107 | J15: LCPH | K15: IFR | L15: S | M15: 1. THIS FLIGHT WAS PREPARED BY NIMROD R. 2. EXTRA FUEL PLANNED FOR POSSIBLE SIRENS. | N15: RTECOORATC LCCC | O15: SUVAS1F SUVAS STEPA APLON A28 BETID BETID1A | P15: 160 | Q15: 2 | R15: 6600 | S15: 2026-03-29T13:27:43Z | T15: 2026-03-29T14:31:16Z | U15: 1.0591667 | V15: 1.2994444 | W15: 1031 | X15: 80 | Y15: 951 | Z15: 990 | AA15: 362 | AB15: 281 | AC15: 300 | AD15: 48 | AE15: 2022 | AF15: 5000 | AG15: 3259 | AH15: 0 | AI15: 80 | AJ15: 163 | AK15: 2026-03-29T13:10:00Z | AL15: 2026-03-29T14:30:01.9922756Z | AM15: 301.67 | AN15: 183.03 | AO15: 73.5 | AP15: 21947 | AQ15: 21867 | AR15: 23000 | AS15: 19925 | AT15: 20915 | AU15: -22 | AV15: 267.98 | AW15: 63.67 | AX15: 1.66 | AY15: FALSE
A16: =CONCATENATE(I16,E16,LEFT(G16,10)) -> HFA108ALCLK2026-03-06 | B16: 8885d9c3a47e4810bd9fbe4f19099ffd | C16: Success | D16: Filed | E16: LCLK | F16: LGAV | G16: 2026-03-06T09:00:00Z | H16: 4XIHE | I16: HFA108A | J16: LGMK | K16: IFR | L16: S | M16: EXTRA FUEL IS PER COMPNAY POLICY DIS. BY AYELET W. | O16: PHA1W PHA M31 GENOS TOSKA M978 VAXOS N128 RDS L995 VARIX VARIX1Q | P16: 160 | Q16: 2 | R16: 700 | S16: 2026-03-06T09:25:05Z | T16: 2026-03-06T11:33:06Z | U16: 2.1336111 | V16: 2.475 | W16: 1729 | X16: 80 | Y16: 1649 | Z16: 820 | AA16: 406 | AB16: 232 | AC16: 100 | AD16: 82 | AE16: 2549 | AF16: 5000 | AG16: 5465 | AH16: 0 | AI16: 139 | AJ16: 216 | AK16: 2026-03-06T09:00:00Z | AL16: 2026-03-06T11:18:59.431665Z | AM16: 570.64 | AN16: 503.3 | AO16: 112.42 | AP16: 16574 | AQ16: 16494 | AR16: 23000 | AS16: 14025 | AT16: 14845 | AU16: -25 | AV16: 312.6 | AW16: 24.22 | AX16: 0.61 | AY16: FALSE
A17: =CONCATENATE(I17,E17,LEFT(G17,10)) -> HFA108LGAV2026-03-06 | B17: d49a69023f8e4ccd92eaf2032321679a | C17: Success | D17: Filed | E17: LGAV | F17: LLBG | G17: 2026-03-06T13:15:00Z | H17: 4XIHE | I17: HFA108 | J17: LCLK | K17: IFR | L17: S | M17: EXTRA FUEL FOR NEXT LEG. NEEDS TO REFUEL AT LLBG FOR NEXT LEG (LLBG-LCLK) DIS. BY AYELET W. | O17: KEA1E KEA L995 RDS/F150 L609 ALKIS/N0274F190 L609 APLON DCT PIKOG L609 ZUKKO AMMOS1A | P17: 190 | Q17: 2 | R17: 6500 | S17: 2026-03-06T13:37:08Z | T17: 2026-03-06T16:08:19Z | U17: 2.5197222 | V17: 2.7663889 | W17: 1787 | X17: 80 | Y17: 1707 | Z17: 1213 | AA17: 740 | AB17: 282 | AC17: 106 | AD17: 85 | AE17: 3000 | AF17: 5000 | AG17: 5647 | AH17: 0 | AI17: 149 | AJ17: 257 | AK17: 2026-03-06T13:15:00Z | AL17: 2026-03-06T15:43:34.5720084Z | AM17: 684.93 | AN17: 645.11 | AO17: 215.32 | AP17: 22825 | AQ17: 22745 | AR17: 23000 | AS17: 19825 | AT17: 21038 | AU17: 21 | AV17: 316.17 | AW17: 26.54 | AX17: 1.59 | AY17: FALSE
A18: =CONCATENATE(I18,E18,LEFT(G18,10)) -> HFA109LLBG2026-03-06 | B18: 70ed7c1fd8754809b4aa6ce2fa5d40d8 | C18: Success | D18: Filed | E18: LLBG | F18: LCLK | G18: 2026-03-06T18:55:00Z | H18: 4XIHB | I18: HFA109 | J18: LCPH | K18: IFR | L18: S | M18: 1. THIS FLIGHT WAS PREPARED BY NIMROD R. | N18: RTECOORATC LCCC | O18: SUVAS STEPA APLON A28 BETID | P18: 160 | Q18: 2 | R18: 700 | S18: 2026-03-06T19:40:39Z | T18: 2026-03-06T20:48:27Z | U18: 1.13 | V18: 1.7202778 | W18: 1061 | X18: 80 | Y18: 981 | Z18: 615 | AA18: 335 | AB18: 231 | AC18: 0 | AD18: 49 | AE18: 1677 | AF18: 5000 | AG18: 3354 | AH18: 0 | AI18: 75 | AJ18: 132 | AK18: 2026-03-06T18:55:00Z | AL18: 2026-03-06T20:10:22.0202161Z | AM18: 299.85 | AN18: 183.03 | AO18: 73.5 | AP18: 15688 | AQ18: 15608 | AR18: 23000 | AS18: 14011 | AT18: 14626 | AU18: -20 | AV18: 297.53 | AW18: 28.6 | AX18: 2.2 | AY18: FALSE
A19: =CONCATENATE(I19,E19,LEFT(G19,10)) -> HFA110ALCLK2026-03-06 | B19: 41f462e6cf284e9181f2c949d561396d | C19: Success | D19: Filed | E19: LCLK | F19: LGAV | G19: 2026-03-06T11:00:00Z | H19: 4XIHB | I19: HFA110A | J19: LGMK | K19: IFR | L19: S | M19: EXTREA FUEL PER COMPNAY POLICY-REDUCED TO 80KG (PER LIOR) DIS. BY AYELET W. | O19: PHA1W PHA M31 GENOS TOSKA M978 VAXOS N128 RDS L995 VARIX VARIX1Q | P19: 160 | Q19: 2 | R19: 500 | S19: 2026-03-06T11:26:45Z | T19: 2026-03-06T13:39:31Z | U19: 2.2127778 | V19: 2.4883333 | W19: 1876 | X19: 80 | Y19: 1796 | Z19: 821 | AA19: 421 | AB19: 230 | AC19: 80 | AD19: 90 | AE19: 2697 | AF19: 5000 | AG19: 5930 | AH19: 0 | AI19: 138 | AJ19: 213 | AK19: 2026-03-06T11:00:00Z | AL19: 2026-03-06T13:17:40.3997241Z | AM19: 570.64 | AN19: 503.3 | AO19: 112.42 | AP19: 16508 | AQ19: 16428 | AR19: 23000 | AS19: 13811 | AT19: 14632 | AU19: -23 | AV19: 315.28 | AW19: 22.85 | AX19: 0.72 | AY19: FALSE
A20: =CONCATENATE(I20,E20,LEFT(G20,10)) -> HFA110LGAV2026-03-06 | B20: d2cc38cb0bcc44e8b5a99278a0e4e4db | C20: Success | D20: Filed | E20: LGAV | F20: LLBG | G20: 2026-03-06T15:15:00Z | H20: 4XIHB | I20: HFA110 | J20: LCLK | K20: IFR | L20: S | M20: OFP REV 01 DUE TO EXTRA FUEL- 300KG EXTRA FUEL FOR THE NEXT LEG NEEDS TO REFUEL AT LLBG FOR NEXT LEG (LLBG-LCLK) DIS. BY AYELET W. | O20: KEA1E KEA L995 RDS/F150 L609 ALKIS/N0274F190 L609 APLON DCT PIKOG L609 ZUKKO GODED2 | P20: 190 | Q20: 2 | R20: 5900 | S20: 2026-03-06T15:31:10Z | T20: 2026-03-06T18:03:29Z | U20: 2.5386111 | V20: 2.7952778 | W20: 1886 | X20: 80 | Y20: 1806 | Z20: 1514 | AA20: 756 | AB20: 279 | AC20: 389 | AD20: 90 | AE20: 3400 | AF20: 5000 | AG20: 5959 | AH20: 0 | AI20: 146 | AJ20: 279 | AK20: 2026-03-06T15:15:00Z | AL20: 2026-03-06T17:40:41.1622023Z | AM20: 671.54 | AN20: 645.11 | AO20: 215.32 | AP20: 22611 | AQ20: 22531 | AR20: 23000 | AS20: 19211 | AT20: 20725 | AU20: 21 | AV20: 319.24 | AW20: 25.74 | AX20: 1.63 | AY20: FALSE
A21: =CONCATENATE(I21,E21,LEFT(G21,10)) -> HFA111LLBG2026-03-06 | B21: ec89f4f96ff743c09717d8a7c91d3709 | C21: Success | D21: Filed | E21: LLBG | F21: LCLK | G21: 2026-03-06T21:10:00Z | H21: 4XIHD | I21: HFA111 | J21: LCPH | K21: IFR | L21: S | M21: 1. THIS FLIGHT WAS PREPARED BY NIMROD R. | N21: DISPATCH 972502126365 RTECOORATC LCCC | O21: SUVAS STEPA APLON A28 BETID | P21: 160 | Q21: 2 | R21: 700 | S21: 2026-03-06T21:21:05Z | T21: 2026-03-06T22:19:16Z | U21: 0.96972222 | V21: 1.225 | W21: 944 | X21: 80 | Y21: 864 | Z21: 591 | AA21: 318 | AB21: 230 | AC21: 0 | AD21: 43 | AE21: 1536 | AF21: 5000 | AG21: 2985 | AH21: 0 | AI21: 74 | AJ21: 130 | AK21: 2026-03-06T21:10:00Z | AL21: 2026-03-06T22:24:25.0715491Z | AM21: 299.85 | AN21: 183.03 | AO21: 73.5 | AP21: 15461 | AQ21: 15381 | AR21: 23000 | AS21: 13925 | AT21: 14516 | AU21: -17 | AV21: 303.6 | AW21: 25.96 | AX21: 1.99 | AY21: FALSE
A22: =CONCATENATE(I22,E22,LEFT(G22,10)) -> HFA112ALCLK2026-03-06 | B22: 172bf7db1fb24bfc83699d5764c244f3 | C22: Success | D22: Cancelled | E22: LCLK | F22: LBSF | G22: 2026-03-06T11:30:00Z | H22: 4XIHD | I22: HFA112A | J22: LBPD | K22: IFR | L22: S | M22: EXTRA FUEL IS PER COMPANY POLICY DIS. BY AYEET W | N22: DISPATCH +972502126365, PASSENGERS FLIGHT | O22: PHA1W PHA M31 MAROS M67 TOSKA M978 VAXOS N128 OKESA DCT RIKSO N128 PEREN L863 EVIVI Y94 VANET VANET5H | P22: 140 | Q22: 4 | R22: 600 | S22: 2026-03-06T11:41:34Z | T22: 2026-03-06T14:42:11Z | U22: 3.0102778 | V22: 3.2519444 | W22: 2424 | X22: 80 | Y22: 2344 | Z22: 798 | AA22: 357 | AB22: 224 | AC22: 100 | AD22: 117 | AE22: 3222 | AF22: 5000 | AG22: 7660 | AH22: 0 | AI22: 192 | AJ22: 271 | AK22: 2026-03-06T11:30:00Z | AL22: 2026-03-06T14:41:51.9508772Z | AM22: 825.19 | AN22: 669.47 | AO22: 102.22 | AP22: 17047 | AQ22: 16967 | AR22: 23000 | AS22: 13825 | AT22: 14623 | AU22: -18 | AV22: 329.11 | AW22: 19.3 | AX22: 0.61 | AY22: FALSE
A23: =CONCATENATE(I23,E23,LEFT(G23,10)) -> HFA112LBSF2026-03-06 | B23: a5cb85f9fcdd4a24896c5eff76c3402f | C23: Success | D23: Filed | E23: LBSF | F23: LLBG | G23: 2026-03-06T17:00:00Z | H23: 4XIHD | I23: HFA112 | J23: LCLK | K23: IFR | L23: S | M23: 1. THIS FLIGHT WAS PREPARED BY NIMROD R. | N23: DISPATCH +972502126365, PASSENGERS FLIGHT | O23: OMENO3S OMENO Y505 NIKTI N127 IMR G80 AKBUK DCT PIROX N129 RDS L609 ZUKKO AMMOS1A | P23: 190 | Q23: 2 | R23: 6500 | S23: 2026-03-06T17:14:25Z | T23: 2026-03-06T20:37:28Z | U23: 3.3841667 | W23: 2114 | X23: 80 | Y23: 2034 | Z23: 1186 | AA23: 732 | AB23: 281 | AC23: 71 | AD23: 102 | AE23: 3300 | AF23: 5000 | AG23: 6680 | AH23: 0 | AI23: 188 | AJ23: 296 | AK23: 2026-03-06T17:00:00Z | AL23: 2026-03-06T20:08:24.1076044Z | AM23: 891.8 | AN23: 841.87 | AO23: 215.32 | AP23: 23025 | AQ23: 22945 | AR23: 23000 | AS23: 19725 | AT23: 20911 | AU23: 27 | AV23: 326.16 | AW23: 29.62 | AX23: 1.07 | AY23: FALSE
A24: =CONCATENATE(I24,E24,LEFT(G24,10)) -> HFA113LLBG2026-03-07 | B24: a5fd3359664d4ff7b7ac6e3390d34d5a | C24: Success | D24: Filed | E24: LLBG | F24: LCLK | G24: 2026-03-07T09:25:00Z | H24: 4XIHE | I24: HFA113 | J24: LCPH | K24: IFR | L24: S | M24: EXTRA FUEL CAN BE VOIDED ,IF NEEDED, WITH LIOR YAVOR APPROVAL. DSP-EREZ Y | N24: RTECOORATC LCCC | O24: SUVAS STEPA APLON A28 BETID | P24: 160 | Q24: 2 | R24: 700 | S24: 2026-03-07T10:58:47Z | T24: 2026-03-07T12:03:32Z | U24: 1.0791667 | V24: 1.3719444 | W24: 958 | X24: 80 | Y24: 878 | Z24: 701 | AA24: 325 | AB24: 232 | AC24: 100 | AD24: 44 | AE24: 1659 | AF24: 5000 | AG24: 3028 | AH24: 0 | AI24: 74 | AJ24: 139 | AK24: 2026-03-07T09:25:00Z | AL24: 2026-03-07T10:39:00.6286336Z | AM24: 299.85 | AN24: 183.03 | AO24: 73.5 | AP24: 15684 | AQ24: 15604 | AR24: 23000 | AS24: 14025 | AT24: 14726 | AU24: -16 | AV24: 294.64 | AW24: 39.21 | AX24: 0.35 | AY24: FALSE
A25: =CONCATENATE(I25,E25,LEFT(G25,10)) -> HFA114LCLK2026-03-07 | B25: 9f0293dd22b549368883be8fa8e529f6 | C25: Success | D25: Filed | E25: LCLK | F25: LLBG | G25: 2026-03-07T07:45:00Z | H25: 4XIHE | I25: HFA114 | J25: LCLK | K25: IFR | L25: S | M25: EXTRA FUEL IS DUE FUEL ONBOARD FOR RTRN FLT +POSS HOLDING. DISP-EREZ Y. | N25: RTECOORATC LCCC | O25: EMEDA2B EMEDA M67 ANANE IDAKU PIKOG L609 ZUKKO | P25: 150 | Q25: 2 | R25: 6800 | S25: 2026-03-07T09:03:52Z | T25: 2026-03-07T10:00:38Z | U25: 0.94611111 | V25: 1.225 | W25: 848 | X25: 80 | Y25: 768 | Z25: 1652 | AA25: 771 | AB25: 290 | AC25: 543 | AD25: 48 | AE25: 2500 | AF25: 5000 | AG25: 2679 | AH25: 0 | AI25: 62 | AJ25: 199 | AK25: 2026-03-07T07:45:00Z | AL25: 2026-03-07T08:46:39.8647171Z | AM25: 264.72 | AN25: 183.03 | AO25: 215.31 | AP25: 22625 | AQ25: 22545 | AR25: 23000 | AS25: 20125 | AT25: 21777 | AU25: 13 | AV25: 294.08 | AW25: 37.05 | AX25: -0.16 | AY25: FALSE
A26: =CONCATENATE(I26,E26,LEFT(G26,10)) -> HFA115LLBG2026-03-07 | B26: cf0ca11a2fc649a3bd330bf780d7a110 | C26: Success | D26: Filed | E26: LLBG | F26: LCLK | G26: 2026-03-07T13:55:00Z | H26: 4XIHC | I26: HFA115 | J26: LCPH | K26: IFR | L26: S | M26: EXTRA FUEL CAN BE VOIDED ,IF NEEDED, WITH LIOR YAVOR APPROVAL(requested for 1700kg). DSP-EREZ Y | N26: RTECOORATC LCCC | O26: SUVAS STEPA APLON A28 BETID | P26: 160 | Q26: 2 | R26: 700 | S26: 2026-03-07T14:07:40Z | T26: 2026-03-07T15:21:16Z | U26: 1.2266667 | V26: 1.5783333 | W26: 1034 | X26: 80 | Y26: 954 | Z26: 666 | AA26: 325 | AB26: 233 | AC26: 61 | AD26: 48 | AE26: 1700 | AF26: 5000 | AG26: 3266 | AH26: 0 | AI26: 79 | AJ26: 141 | AK26: 2026-03-07T13:55:00Z | AL26: 2026-03-07T15:14:05.5950354Z | AM26: 299.85 | AN26: 183.03 | AO26: 73.5 | AP26: 15900 | AQ26: 15820 | AR26: 23000 | AS26: 14200 | AT26: 14866 | AU26: -33 | AV26: 320.54 | AW26: 39.51 | AX26: 2.04 | AY26: FALSE
A27: =CONCATENATE(I27,E27,LEFT(G27,10)) -> HFA116LCLK2026-03-07 | B27: 42230916b4514ac6940324cb99246f48 | C27: Success | D27: Filed | E27: LCLK | F27: LLBG | G27: 2026-03-07T09:15:00Z | H27: 4XIHC | I27: HFA116 | J27: LCLK | K27: IFR | L27: S | M27: EXTRA FUEL IS LIMITED DUE HIGH ZFW AND T/O WGT(A/C WAS FUELED A DAY AHEAD). DISP-EREZ Y. | N27: RTECOORATC LCCC | O27: EMEDA2B EMEDA M67 ANANE IDAKU PIKOG L609 ZUKKO | P27: 150 | Q27: 2 | R27: 7200 | S27: 2026-03-07T10:59:20Z | T27: 2026-03-07T11:52:20Z | U27: 0.88333333 | V27: 1.0236111 | W27: 862 | X27: 80 | Y27: 782 | Z27: 1238 | AA27: 775 | AB27: 292 | AC27: 123 | AD27: 49 | AE27: 2100 | AF27: 5000 | AG27: 2722 | AH27: 0 | AI27: 61 | AJ27: 164 | AK27: 2026-03-07T09:15:00Z | AL27: 2026-03-07T10:16:13.281061Z | AM27: 264.72 | AN27: 183.03 | AO27: 215.32 | AP27: 22800 | AQ27: 22720 | AR27: 23000 | AS27: 20700 | AT27: 21938 | AU27: 15 | AV27: 294.47 | AW27: 38.36 | AX27: -0.64 | AY27: FALSE
A28: =CONCATENATE(I28,E28,LEFT(G28,10)) -> HFA117LLBG2026-03-07 | B28: e3d3225ce485401e83a058ac9ada3eee | C28: Success | D28: Filed | E28: LLBG | F28: LCLK | G28: 2026-03-07T09:55:00Z | H28: 4XIHB | I28: HFA117 | J28: LCPH | K28: IFR | L28: S | M28: EXTRA FUEL CAN BE VOIDED ,IF NEEDED, WITH LIOR YAVOR APPROVAL. DSP-EREZ Y | N28: RTECOORATC LCCC | O28: SUVAS STEPA APLON A28 BETID | P28: 160 | Q28: 2 | R28: 700 | S28: 2026-03-07T11:58:55Z | T28: 2026-03-07T13:01:36Z | U28: 1.0447222 | V28: 1.2502778 | W28: 1061 | X28: 80 | Y28: 981 | Z28: 722 | AA28: 341 | AB28: 232 | AC28: 100 | AD28: 49 | AE28: 1783 | AF28: 5000 | AG28: 3353 | AH28: 0 | AI28: 74 | AJ28: 139 | AK28: 2026-03-07T09:55:00Z | AL28: 2026-03-07T11:09:27.7077624Z | AM28: 299.85 | AN28: 183.03 | AO28: 73.5 | AP28: 15794 | AQ28: 15714 | AR28: 23000 | AS28: 14011 | AT28: 14733 | AU28: -17 | AV28: 294.6 | AW28: 39.18 | AX28: 0.27 | AY28: FALSE
A29: =CONCATENATE(I29,E29,LEFT(G29,10)) -> HFA118LCLK2026-03-07 | B29: 88a14f68e52743f6bb0c4bb8152c65b9 | C29: Success | D29: Filed | E29: LCLK | F29: LLBG | G29: 2026-03-07T08:15:00Z | H29: 4XIHB | I29: HFA118 | J29: LCLK | K29: IFR | L29: S | M29: EXTRA FUEL IS FOR THE NEXT FLT+POSS HOLD IN AND OUT OF LLBG. DISP-EREZ Y. | N29: RTECOORATC LCCC | O29: EMEDA2B EMEDA M67 ANANE IDAKU PIKOG L609 ZUKKO | P29: 150 | Q29: 2 | R29: 6500 | S29: 2026-03-07T10:12:58Z | T29: 2026-03-07T11:11:32Z | U29: 0.97611111 | V29: 1.1447222 | W29: 928 | X29: 80 | Y29: 848 | Z29: 1772 | AA29: 775 | AB29: 288 | AC29: 661 | AD29: 48 | AE29: 2700 | AF29: 5000 | AG29: 2933 | AH29: 0 | AI29: 61 | AJ29: 206 | AK29: 2026-03-07T08:15:00Z | AL29: 2026-03-07T09:16:26.9566462Z | AM29: 264.72 | AN29: 183.03 | AO29: 215.32 | AP29: 22511 | AQ29: 22431 | AR29: 23000 | AS29: 19811 | AT29: 21583 | AU29: 14 | AV29: 293.96 | AW29: 37.37 | AX29: -0.33 | AY29: FALSE
A30: =CONCATENATE(I30,E30,LEFT(G30,10)) -> HFA119LLBG2026-03-07 | B30: a09b372460bf4e219391b26bebf21948 | C30: Success | D30: Filed | E30: LLBG | F30: LCLK | G30: 2026-03-07T11:25:00Z | H30: 4XIHD | I30: HFA119 | J30: LCPH | K30: IFR | L30: S | M30: EXTRA FUEL CAN BE VOIDED ,IF NEEDED, WITH LIOR YAVOR APPROVAL(requested for 1600kg). DSP-EREZ Y | N30: DISPATCH 972502126365 RTECOORATC LCCC | O30: SUVAS STEPA APLON A28 BETID | P30: 160 | Q30: 2 | R30: 700 | S30: 2026-03-07T12:41:58Z | T30: 2026-03-07T14:01:48Z | U30: 1.3305556 | V30: 1.605 | W30: 971 | X30: 80 | Y30: 891 | Z30: 629 | AA30: 323 | AB30: 230 | AC30: 31 | AD30: 45 | AE30: 1600 | AF30: 5000 | AG30: 3070 | AH30: 0 | AI30: 76 | AJ30: 135 | AK30: 2026-03-07T11:25:00Z | AL30: 2026-03-07T12:41:04.4656009Z | AM30: 299.85 | AN30: 183.03 | AO30: 73.5 | AP30: 15525 | AQ30: 15445 | AR30: 23000 | AS30: 13925 | AT30: 14554 | AU30: -24 | AV30: 300.24 | AW30: 40.43 | AX30: 0.51 | AY30: FALSE
A31: =CONCATENATE(I31,E31,LEFT(G31,10)) -> HFA120ALCLK2026-03-07 | B31: 88d4bee3893e4990ac27ad40436002a1 | C31: Success | D31: Filed | E31: LCLK | F31: LGAV | G31: 2026-03-07T05:00:00Z | H31: 4XIHD | I31: HFA120A | J31: LGIR | K31: IFR | L31: S | M31: EXTRA FUEL IS DUE FUEL ON BOARD. DISP-EREZ Y. | N31: DISPATCH +972502126365 | O31: N0283F160 PHA1W PHA M31 GENOS DCT ALKIS L609 RDS L995 VARIX VARIX1Q | P31: 160 | Q31: 2 | R31: 700 | S31: 2026-03-07T05:45:51Z | T31: 2026-03-07T08:00:15Z | U31: 2.24 | V31: 2.7436111 | W31: 1679 | X31: 80 | Y31: 1599 | Z31: 1121 | AA31: 547 | AB31: 233 | AC31: 262 | AD31: 80 | AE31: 2800 | AF31: 5000 | AG31: 5306 | AH31: 0 | AI31: 137 | AJ31: 243 | AK31: 2026-03-07T05:00:00Z | AL31: 2026-03-07T07:17:24.0699699Z | AM31: 555.76 | AN31: 503.3 | AO31: 176.85 | AP31: 16725 | AQ31: 16645 | AR31: 23000 | AS31: 13925 | AT31: 15046 | AU31: -27 | AV31: 326.43 | AW31: 29.6 | AX31: 0.93 | AY31: FALSE
A32: =CONCATENATE(I32,E32,LEFT(G32,10)) -> HFA120LGAV2026-03-07 | B32: dc0b7e8bf0d14be989c1a4041767cc1b | C32: Success | D32: Filed | E32: LGAV | F32: LLBG | G32: 2026-03-07T08:15:00Z | H32: 4XIHD | I32: HFA120 | J32: LCLK | K32: IFR | L32: S | M32: 1.PAY ATTN TO T/O NEAR MAX T/O WGT(EXTRA FUEL OF 100 CAN BE VOIDED ,IF NEEDED PER LIOR YAVOR). DISP-EREZ Y. | N32: DISPATCH +972502126365 | O32: N0267F190 KEA1E KEA L52 VAXOS N134 VANZA/N0268F190 DCT PIKOG L609 ZUKKO AMMOS1A | P32: 190 | Q32: 2 | R32: 6600 | S32: 2026-03-07T09:00:43Z | T32: 2026-03-07T11:25:34Z | U32: 2.4141667 | V32: 2.575 | W32: 1717 | X32: 80 | Y32: 1637 | Z32: 1210 | AA32: 746 | AB32: 282 | AC32: 100 | AD32: 82 | AE32: 2927 | AF32: 5000 | AG32: 5427 | AH32: 0 | AI32: 148 | AJ32: 252 | AK32: 2026-03-07T08:15:00Z | AL32: 2026-03-07T10:42:40.1145216Z | AM32: 682.75 | AN32: 645.11 | AO32: 215.31 | AP32: 22752 | AQ32: 22672 | AR32: 23000 | AS32: 19825 | AT32: 21035 | AU32: 22 | AV32: 329.95 | AW32: 30.98 | AX32: 1.57 | AY32: FALSE
A33: =CONCATENATE(I33,E33,LEFT(G33,10)) -> HFA121LLBG2026-03-07 | B33: 1d7906eee2a64d3d9a2a66986e30c88f | C33: Success | D33: Filed | E33: LLBG | F33: LCLK | G33: 2026-03-07T11:55:00Z | H33: 4XIHA | I33: HFA121 | J33: LCPH | K33: IFR | L33: S | M33: EXTRA FUEL IS PER POLICY. DISP-EREZ Y. | N33: DISPATCH 972502126365 RTECOORATC LCCC | O33: SUVAS STEPA APLON A28 BETID | P33: 160 | Q33: 2 | R33: 700 | S33: 2026-03-07T12:54:27Z | T33: 2026-03-07T14:23:23Z | U33: 1.4822222 | V33: 1.7511111 | W33: 1001 | X33: 80 | Y33: 921 | Z33: 703 | AA33: 326 | AB33: 231 | AC33: 100 | AD33: 46 | AE33: 1705 | AF33: 5000 | AG33: 3165 | AH33: 0 | AI33: 77 | AJ33: 142 | AK33: 2026-03-07T11:55:00Z | AL33: 2026-03-07T13:12:08.2386425Z | AM33: 299.85 | AN33: 183.03 | AO33: 73.5 | AP33: 15610 | AQ33: 15530 | AR33: 23000 | AS33: 13905 | AT33: 14608 | AU33: -27 | AV33: 303.55 | AW33: 40.86 | AX33: 0.79 | AY33: FALSE
A34: =CONCATENATE(I34,E34,LEFT(G34,10)) -> HFA122LBSF2026-03-07 | B34: 82fa7b35ad964b5e864086fd2e6f9156 | C34: Success | D34: Filed | E34: LBSF | F34: LLBG | G34: 2026-03-07T08:00:00Z | H34: 4XIHA | I34: HFA122 | J34: LCLK | K34: IFR | L34: S | M34: EXTRA FUEL POLICY WAS TEMPORARLILY VOIDED DUE TO T/O WGT,AS PER LIOR YAVOR APPROVAL. DISP-EREZ Y. | N34: DISPATCH +972502126365, PASSENGERS FLIGHT | O34: OMENO3S OMENO Y505 NIKTI N127 IMR G80 AKBUK PIROX N129 RDS L609 EVUNU/N0264F210 L609 ZUKKO AMMOS1A | P34: 190 | Q34: 2 | R34: 6500 | S34: 2026-03-07T08:24:52Z | T34: 2026-03-07T11:37:57Z | U34: 3.2180556 | V34: 3.4363889 | W34: 2160 | X34: 80 | Y34: 2080 | Z34: 1143 | AA34: 758 | AB34: 280 | AC34: 0 | AD34: 104 | AE34: 3303 | AF34: 5000 | AG34: 6826 | AH34: 0 | AI34: 190 | AJ34: 287 | AK34: 2026-03-07T08:00:00Z | AL34: 2026-03-07T11:09:36.7765963Z | AM34: 891.8 | AN34: 841.87 | AO34: 215.32 | AP34: 23008 | AQ34: 22928 | AR34: 23000 | AS34: 19705 | AT34: 20848 | AU34: 26 | AV34: 341.62 | AW34: 31.83 | AX34: 1.13 | AY34: FALSE
A35: =CONCATENATE(I35,E35,LEFT(G35,10)) -> HFA123LLBG2026-03-07 | B35: 0e55e2bfb0e047e284e841029e35246a | C35: Success | D35: Filed | E35: LLBG | F35: LCLK | G35: 2026-03-07T19:25:00Z | H35: 4XIHE | I35: HFA123 | J35: LCPH | K35: IFR | L35: S | M35: 1. THIS FLIGHT WAS PREPARED BY NIMROD R. | N35: RTECOORATC LCCC | O35: SUVAS STEPA APLON A28 BETID | P35: 160 | Q35: 2 | R35: 700 | S35: 2026-03-07T19:45:05Z | T35: 2026-03-07T21:03:06Z | U35: 1.3002778 | V35: 1.5394444 | W35: 958 | X35: 80 | Y35: 878 | Z35: 589 | AA35: 314 | AB35: 231 | AC35: 0 | AD35: 44 | AE35: 1546 | AF35: 5000 | AG35: 3026 | AH35: 0 | AI35: 75 | AJ35: 130 | AK35: 2026-03-07T19:25:00Z | AL35: 2026-03-07T20:39:46.2658373Z | AM35: 299.85 | AN35: 183.03 | AO35: 73.5 | AP35: 15572 | AQ35: 15492 | AR35: 23000 | AS35: 14025 | AT35: 14614 | AU35: -19 | AV35: 322.82 | AW35: 30.79 | AX35: 2.5 | AY35: FALSE
... A41: =CONCATENATE(I41,E41,LEFT(G41,10)) -> HFA130LCLK2026-03-08 | B41: ee22e0ff21ca4a96933f3b1e30ef35e1 | C41: Success | D41: Filed | E41: LCLK | F41: LLBG | G41: 2026-03-08T05:00:00Z | H41: 4XIHD | I41: HFA130 | J41: LCLK | K41: IFR | L41: S | M41: OFP REV 01 DUE TO CHG IN ZFW. EXTAR FUEL FOR THE NEXT LEG+POSS HOLIDING. DIS. BY AYELET W. | N41: DISPATCH 972502126365 RTECOORATC LCCC | O41: EMEDA2B EMEDA M67 ANANE IDAKU PIKOG L609 ZUKKO | P41: 150 | Q41: 2 | R41: 0 | S41: 2026-03-08T05:57:51Z | T41: 2026-03-08T06:51:34Z | U41: 0.89527778 | V41: 1.0441667 | W41: 816 | X41: 80 | Y41: 736 | Z41: 1784 | AA41: 741 | AB41: 279 | AC41: 717 | AD41: 47 | AE41: 2600 | AF41: 5000 | AG41: 2580 | AH41: 0 | AI41: 61 | AJ41: 213 | AK41: 2026-03-08T05:00:00Z | AL41: 2026-03-08T06:00:35.3136124Z | AM41: 264.72 | AN41: 183.03 | AO41: 215.32 | AP41: 21532 | AQ41: 21452 | AR41: 23000 | AS41: 18932 | AT41: 20716 | AU41: 16 | AV41: 327.5 | AW41: 25.22 | AX41: 1.75 | AY41: FALSE
A42: =CONCATENATE(I42,E42,LEFT(G42,10)) -> HFA131ALCLK2026-03-29 | B42: f55c290953374b419c269049102b7350 | C42: Success | D42: None | E42: LCLK | F42: LGAV | G42: 2026-03-29T07:30:00Z | H42: 4XIHB | I42: HFA131A | J42: LGIR | K42: IFR | L42: G | M42: 1. THIS FLIGHT WAS PREPARED BY NIMROD R. | N42: FERRY FLIGHT | O42: PHA1W PHA M31 MAROS L609 ALKIS/F220 L609 EVUNU L609 NILAS/F240 L609 RDS L995 VARIX VARIX1Q | P42: 200 | Q42: 2 | R42: 500 | W42: 1742 | X42: 80 | Y42: 1662 | Z42: 892 | AA42: 578 | AB42: 230 | AC42: 0 | AD42: 83 | AE42: 2634 | AF42: 5000 | AG42: 5505 | AH42: 0 | AI42: 145 | AJ42: 227 | AK42: 2026-03-29T07:30:00Z | AL42: 2026-03-29T09:55:27.3708185Z | AM42: 563.31 | AN42: 503.3 | AO42: 176.85 | AP42: 16445 | AQ42: 16365 | AR42: 23000 | AS42: 13811 | AT42: 14703 | AU42: -36 | AV42: 256.96 | AW42: 43.76 | AX42: -5.38 | AY42: FALSE
A43: =CONCATENATE(I43,E43,LEFT(G43,10)) -> HFA131LCLK2026-03-29 | B43: adad49e6a98e42389e6c16ae164676bf | C43: Success | D43: Filed | E43: LCLK | F43: LFBF | G43: 2026-03-29T07:45:00Z | H43: 4XIHB | I43: HFA131 | J43: LFBO | K43: IFR | L43: G | M43: 1. THIS FLIGHT WAS PREPARED BY NIMROD R. 2. FLIGHT PLAN MAY BE OPERATIONAL ONCE ENOUGH FUELED SAVED TO PROCEED TO LFBF. | N43: FERRY FLIGHT | O43: PHA1W PHA M31 GENOS DCT TOSKA M978 PERIM L53 KRK L869 LATAN/N0282F180 L869 CDC Q182 MINKA/N0279F240 Q182 MALAV DCT EPIKU DCT GINOX DCT OKSER DCT AMFAC/N0277F250 DCT FJR DCT AFRIC AFRIC3S | P43: 220 | Q43: 2 | R43: 500 | S43: 2026-03-29T08:01:22Z | T43: 2026-03-29T15:09:09Z | U43: 7.1297222 | V43: 7.3525 | W43: 4679 | X43: 30 | Y43: 4649 | Z43: 512 | AA43: 222 | AB43: 225 | AC43: 0 | AD43: 65 | AE43: 5191 | AF43: 5000 | AG43: 14787 | AH43: 0 | AI43: 416 | AJ43: 469 | AK43: 2026-03-29T07:45:00Z | AL43: 2026-03-29T14:40:35.7434033Z | AM43: 1734.63 | AN43: 1580.46 | AO43: 45 | AP43: 19002 | AQ43: 18972 | AR43: 23000 | AS43: 13811 | AT43: 14323 | AU43: -23 | AV43: 300.32 | AW43: 23.21 | AX43: -3.59 | AY43: FALSE
